sqlalchemy.exc.ArgumentError: ORDER BY expression expected, got <property object at 0x7fe132e13920>.

Traceback (most recent call last)
File "/opt/venv/lib/python3.12/site-packages/flask/app.py", line 1536, in __call__
return self.wsgi_app(environ, start_response)
       ^^^^^^^^^^^^^^^^^^^^^^^^^^^^^^^^^^^^^^
File "/opt/venv/lib/python3.12/site-packages/werkzeug/middleware/proxy_fix.py", line 183, in __call__
return self.app(environ, start_response)
       ^^^^^^^^^^^^^^^^^^^^^^^^^^^^^^^^^
File "/opt/venv/lib/python3.12/site-packages/flask/app.py", line 1514, in wsgi_app
response = self.handle_exception(e)
           ^^^^^^^^^^^^^^^^^^^^^^^^
File "/opt/venv/lib/python3.12/site-packages/flask/app.py", line 1511, in wsgi_app
response = self.full_dispatch_request()
           ^^^^^^^^^^^^^^^^^^^^^^^^^^^^
File "/opt/venv/lib/python3.12/site-packages/flask/app.py", line 919, in full_dispatch_request
rv = self.handle_user_exception(e)
     ^^^^^^^^^^^^^^^^^^^^^^^^^^^^^
File "/opt/venv/lib/python3.12/site-packages/flask/app.py", line 917, in full_dispatch_request
rv = self.dispatch_request()
     ^^^^^^^^^^^^^^^^^^^^^^^
File "/opt/venv/lib/python3.12/site-packages/flask/app.py", line 902, in dispatch_request
return self.ensure_sync(self.view_functions[rule.endpoint])(**view_args)  # type: ignore[no-any-return]
       ^^^^^^^^^^^^^^^^^^^^^^^^^^^^^^^^^^^^^^^^^^^^^^^^^^^^^^^^^^^^^^^^^
File "/opt/venv/lib/python3.12/site-packages/flask_login/utils.py", line 290, in decorated_view
return current_app.ensure_sync(func)(*args, **kwargs)
       ^^^^^^^^^^^^^^^^^^^^^^^^^^^^^^^^^^^^^^^^^^^^^^
File "/app/routes.py", line 3562, in new_vehicle_maintenance
form = VehicleMaintenanceForm()
       ^^^^^^^^^^^^^^^^^^^^^^^^
File "/opt/venv/lib/python3.12/site-packages/wtforms/form.py", line 209, in __call__
return type.__call__(cls, *args, **kwargs)
       ^^^^^^^^^^^^^^^^^^^^^^^^^^^^^^^^^^^
File "/app/forms.py", line 455, in __init__
for v in Vehicle.query.order_by(Vehicle.identifier).all()]
         ^^^^^^^^^^^^^^^^^^^^^^^^^^^^^^^^^^^^^^^^^^
File "<string>", line 2, in order_by
File "/opt/venv/lib/python3.12/site-packages/sqlalchemy/sql/base.py", line 280, in _generative
x = fn(self, *args, **kw)
    ^^^^^^^^^^^^^^^^^^^^^
File "/opt/venv/lib/python3.12/site-packages/sqlalchemy/orm/query.py", line 2040, in order_by
criterion = tuple(
            
File "/opt/venv/lib/python3.12/site-packages/sqlalchemy/orm/query.py", line 2041, in <genexpr>
coercions.expect(roles.OrderByRole, clause)
^^^^^^^^^^^^^^^^^^^^^^^^^^^^^^^^^^^^^^^^^^^
File "/opt/venv/lib/python3.12/site-packages/sqlalchemy/sql/coercions.py", line 395, in expect
resolved = impl._literal_coercion(
           
File "/opt/venv/lib/python3.12/site-packages/sqlalchemy/sql/coercions.py", line 634, in _literal_coercion
self._raise_for_expected(element, argname)
^^^^^^^^^^^^^^^^^^^^^^^^^^^^^^^^^^^^^^^^^^
File "/opt/venv/lib/python3.12/site-packages/sqlalchemy/sql/coercions.py", line 518, in _raise_for_expected
raise exc.ArgumentError(msg, code=code) from err
^^^^^^^^^^^^^^^^^^^^^^^^^^^^^^^^^^^^^^^^^^^^^^^^
sqlalchemy.exc.ArgumentError: ORDER BY expression expected, got <property object at 0x7fe132e13920>.
The debugger caught an exception in your WSGI application. You can now look at the traceback which led to the error.
To switch between the interactive traceback and the plaintext one, you can click on the "Traceback" headline. From the text traceback you can also create a paste of it.